W0105 22:06:28.124000 2200330 site-packages/torch/distributed/run.py:793] 
W0105 22:06:28.124000 2200330 site-packages/torch/distributed/run.py:793] *****************************************
W0105 22:06:28.124000 2200330 site-packages/torch/distributed/run.py:793] Setting OMP_NUM_THREADS environment variable for each process to be 1 in default, to avoid your system being overloaded, please further tune the variable for optimal performance in your application as needed. 
W0105 22:06:28.124000 2200330 site-packages/torch/distributed/run.py:793] *****************************************
/home/xinyuzh/anaconda3/envs/meditron/bin/python: can't open file '/playpen/xinyu/Jesse/dg_tunning/combine_exp/baseline/tune_dialogue.py': [Errno 2] No such file or directory
/home/xinyuzh/anaconda3/envs/meditron/bin/python: can't open file '/playpen/xinyu/Jesse/dg_tunning/combine_exp/baseline/tune_dialogue.py': [Errno 2] No such file or directory
/home/xinyuzh/anaconda3/envs/meditron/bin/python: can't open file '/playpen/xinyu/Jesse/dg_tunning/combine_exp/baseline/tune_dialogue.py': [Errno 2] No such file or directory
/home/xinyuzh/anaconda3/envs/meditron/bin/python: can't open file '/playpen/xinyu/Jesse/dg_tunning/combine_exp/baseline/tune_dialogue.py': [Errno 2] No such file or directory
E0105 22:06:28.236000 2200330 site-packages/torch/distributed/elastic/multiprocessing/api.py:869] failed (exitcode: 2) local_rank: 0 (pid: 2200406) of binary: /home/xinyuzh/anaconda3/envs/meditron/bin/python
Traceback (most recent call last):
  File "/home/xinyuzh/anaconda3/envs/meditron/bin/torchrun", line 8, in <module>
    sys.exit(main())
  File "/home/xinyuzh/anaconda3/envs/meditron/lib/python3.10/site-packages/torch/distributed/elastic/multiprocessing/errors/__init__.py", line 355, in wrapper
    return f(*args, **kwargs)
  File "/home/xinyuzh/anaconda3/envs/meditron/lib/python3.10/site-packages/torch/distributed/run.py", line 919, in main
    run(args)
  File "/home/xinyuzh/anaconda3/envs/meditron/lib/python3.10/site-packages/torch/distributed/run.py", line 910, in run
    elastic_launch(
  File "/home/xinyuzh/anaconda3/envs/meditron/lib/python3.10/site-packages/torch/distributed/launcher/api.py", line 138, in __call__
    return launch_agent(self._config, self._entrypoint, list(args))
  File "/home/xinyuzh/anaconda3/envs/meditron/lib/python3.10/site-packages/torch/distributed/launcher/api.py", line 269, in launch_agent
    raise ChildFailedError(
torch.distributed.elastic.multiprocessing.errors.ChildFailedError: 
============================================================
tune_dialogue.py FAILED
------------------------------------------------------------
Failures:
[1]:
  time      : 2025-01-05_22:06:28
  host      : unites4.cs.unc.edu
  rank      : 1 (local_rank: 1)
  exitcode  : 2 (pid: 2200407)
  error_file: <N/A>
  traceback : To enable traceback see: https://pytorch.org/docs/stable/elastic/errors.html
[2]:
  time      : 2025-01-05_22:06:28
  host      : unites4.cs.unc.edu
  rank      : 2 (local_rank: 2)
  exitcode  : 2 (pid: 2200408)
  error_file: <N/A>
  traceback : To enable traceback see: https://pytorch.org/docs/stable/elastic/errors.html
[3]:
  time      : 2025-01-05_22:06:28
  host      : unites4.cs.unc.edu
  rank      : 3 (local_rank: 3)
  exitcode  : 2 (pid: 2200409)
  error_file: <N/A>
  traceback : To enable traceback see: https://pytorch.org/docs/stable/elastic/errors.html
------------------------------------------------------------
Root Cause (first observed failure):
[0]:
  time      : 2025-01-05_22:06:28
  host      : unites4.cs.unc.edu
  rank      : 0 (local_rank: 0)
  exitcode  : 2 (pid: 2200406)
  error_file: <N/A>
  traceback : To enable traceback see: https://pytorch.org/docs/stable/elastic/errors.html
============================================================
